{"timestamp":"1447284512","author":"ckerur","description":"Overall Looks good. "}

{"timestamp":"1447284512","author":"ckerur","location":{"commit":"a3f462b139c47923e69b34b7c43cf63d3866560d","path":"commands/output/output.go","range":{"startLine":83}},"description":"Can an exception be thrown here ?"}

{"timestamp":"1447284512","author":"ckerur","location":{"commit":"a3f462b139c47923e69b34b7c43cf63d3866560d","path":"commands/output/output.go","range":{"startLine":56}},"description":"this method is a little confusing to read.\n\nConsider changing  into 2 methods -one that calculates status and the other that does the printing ...\n\nThat way this method could look like\n\nif(r.Resolved == nil and r.Submitted)\n  return \"tbr\"\nif(r.Resolved == nil)\nreturn \"pending\"\n\nif (*r.Resolved ){\n    if(r.Submitted) {\n        return \"submitted\"\n   }\n   else return \"rejected\"\n}\n\nif(r.submitted)\n   return \"danger\"...\n\n\n"}

{"timestamp":"1447350213","author":"ojarjur@google.com","parent":"84dcc530c84be282f2491ebd6891a005543691dc","location":{"commit":"a3f462b139c47923e69b34b7c43cf63d3866560d"},"description":"No, no exceptions can come out of this. The method is meant to be safe for any string; if it sees one that it doesn't know how to handle, then it just leaves it alone."}

{"timestamp":"1447350868","author":"ojarjur@google.com","parent":"5b43306eea8f2413a394f70224289468b8020a5c","location":{"commit":"a3f462b139c47923e69b34b7c43cf63d3866560d"},"description":"Done","resolved":true}
